Workbook

Sheet Read Me First
A1: PredSea — Bottom-Up Growth & Series A Readiness Model
A3: How to use this workbook
A4: 1. Every BLUE cell is an input you control. Every BLACK cell is a formula — do not overwrite it.
A5: 2. Start with the 'Assumptions' tab. The most important cells are highlighted YELLOW — these are
A6: currently placeholders and materially change the output. Replace them with real sourced numbers
A7: (port authority / charter association vessel counts, actual pilot churn once you have more weeks of data).
A8: 3. 'Monthly Model' builds a 48-month (Year 1-4) cohort model: new logos, churn, seasonality, MRR, cash burn.
A9: It is capped by the addressable-vessel ceiling in Assumptions, so it cannot grow past what is countable.
A10: 4. 'Annual Summary' rolls the monthly model into the Year 1/2/3/4 view for your pitch deck and business plan.
A11: 5. 'Series A Dashboard' translates your monthly numbers into the specific metrics investors check before
A12: funding a Series A, with pass/fail thresholds you can adjust. Use this to know, month by month, how close
A13: you actually are — rather than assuming a fixed 12-month calendar date.
... A21: - Real founder-draw ramp timing (when bootstrap ends and full €65K/year draw begins) — currently a placeholder tied to Series A phase milestones.

Sheet Assumptions
A1: Assumptions — edit the BLUE cells
A3: Assumption | B3: Value | C3: Notes / source needed
A4: MARKET SIZING (addressable vessel ceilings)
A5: Addressable vessels — Balearics (Year 1 ceiling) | B5: 1200 | C5: PLACEHOLDER — replace with port authority / ANEN / charter association count
A6: Addressable vessels — + mainland Spain & Italy (Year 2 ceiling) | B6: 4500 | C6: PLACEHOLDER — sum of Y1 + additional country counts
A7: Addressable vessels — + France & Monaco (Year 3 ceiling) | B7: 9000 | C7: PLACEHOLDER — sum of Y2 + additional country counts
A8: Addressable vessels — wider West Med + adjacent segments (Year 4 ceiling) | B8: 15000 | C8: PLACEHOLDER — long-term SAM approach
A9: PRICING & MIX
A10: Premium Route price (EUR / vessel / month) | B10: 49 | C10: From business plan Section 6.1
A11: Corporate / Fleet blended price (EUR / vessel / month) | B11: 39.2 | C11: UPDATED — 20% volume discount off Premium (49 x 0.8 = 39.2), per founder guidance on typical fleet-deal discounting. Refine with first real fleet deal.
A12: % of vessels on Corporate/Fleet pricing (blend, by Year 3) | B12: 0.3 | C12: Placeholder — refine as fleet deals close
A13: GROWTH & CHURN (monthly rates by phase)
A14: Monthly logo growth rate — Months 1-6 (pilot→seed) | B14: 0.35 | C14: Small base, so % growth is naturally high — sanity-check against absolute adds in Monthly Model
A15: Monthly logo growth rate — Months 7-18 (scale/Series A) | B15: 0.14 | C15: Placeholder — benchmark against realized pilot conversion once available
A16: Monthly logo growth rate — Months 19-36 | B16: 0.08 | C16: Placeholder — growth naturally decelerates as ceiling approaches
A17: Monthly logo growth rate — Months 37-48 | B17: 0.05 | C17: Placeholder
A18: Monthly logo churn rate (of active base) | B18: 0.02 | C18: Placeholder — replace with real pilot churn after a full season
A19: SEASONALITY (% of logo base actively paying, by calendar month)
A20: Seasonal active % — Jan | B20: 0.35 | C20: Placeholder — refine once pilot shows real off-season pause/renewal behavior
A21: Seasonal active % — Feb | B21: 0.35 | C21: Placeholder — refine once pilot shows real off-season pause/renewal behavior
A22: Seasonal active % — Mar | B22: 0.55 | C22: Placeholder — refine once pilot shows real off-season pause/renewal behavior
A23: Seasonal active % — Apr | B23: 0.85 | C23: Placeholder — refine once pilot shows real off-season pause/renewal behavior
A24: Seasonal active % — May | B24: 1 | C24: Placeholder — refine once pilot shows real off-season pause/renewal behavior
A25: Seasonal active % — Jun | B25: 1 | C25: Placeholder — refine once pilot shows real off-season pause/renewal behavior
A26: Seasonal active % — Jul | B26: 1 | C26: Placeholder — refine once pilot shows real off-season pause/renewal behavior
A27: Seasonal active % — Aug | B27: 1 | C27: Placeholder — refine once pilot shows real off-season pause/renewal behavior
A28: Seasonal active % — Sep | B28: 1 | C28: Placeholder — refine once pilot shows real off-season pause/renewal behavior
A29: Seasonal active % — Oct | B29: 0.85 | C29: Placeholder — refine once pilot shows real off-season pause/renewal behavior
A30: Seasonal active % — Nov | B30: 0.45 | C30: Placeholder — refine once pilot shows real off-season pause/renewal behavior
A31: Seasonal active % — Dec | B31: 0.35 | C31: Placeholder — refine once pilot shows real off-season pause/renewal behavior
A32: UNIT ECONOMICS
A33: Gross margin % | B33: 0.85 | C33: From business plan Section 13.2
A34: CAC per vessel (EUR) | B34: 150 | C34: PLACEHOLDER — replace with real pilot BD/marketing cost per onboarded captain
A35: Average customer lifetime (months, before churn) | B35: 24 | C35: Cross-check: 1/monthly churn rate — see Series A Dashboard
A36: COSTS (annual operating burn, EUR)
A37: Year 1 annual burn — personnel, marketing & other (excl. cloud infra & AI tokens, modeled separately below) | B37: =(B81*B75+B82)*(1+B83) -> 339250 | C37: Now a formula: (founder cost x headcount + marketing budget) x (1 + contingency). All 4 years share the same baseline on purpose — team growth (sales hire, optional Caribbean hire) shows up as its own explicit, separate line in Monthly Model instead of being buried inside an escalating lump sum. Override any single year manually if you want it to diverge.
A38: Year 2 annual burn — personnel, marketing & other (excl. cloud infra & AI tokens) | B38: =B37 -> 339250 | C38: Now a formula: (founder cost x headcount + marketing budget) x (1 + contingency). All 4 years share the same baseline on purpose — team growth (sales hire, optional Caribbean hire) shows up as its own explicit, separate line in Monthly Model instead of being buried inside an escalating lump sum. Override any single year manually if you want it to diverge.
A39: Year 3 annual burn — personnel, marketing & other (excl. cloud infra & AI tokens) | B39: =B37 -> 339250 | C39: Now a formula: (founder cost x headcount + marketing budget) x (1 + contingency). All 4 years share the same baseline on purpose — team growth (sales hire, optional Caribbean hire) shows up as its own explicit, separate line in Monthly Model instead of being buried inside an escalating lump sum. Override any single year manually if you want it to diverge.
A40: Year 4 annual burn — personnel, marketing & other (excl. cloud infra & AI tokens) | B40: =B37 -> 339250 | C40: Now a formula: (founder cost x headcount + marketing budget) x (1 + contingency). All 4 years share the same baseline on purpose — team growth (sales hire, optional Caribbean hire) shows up as its own explicit, separate line in Monthly Model instead of being buried inside an escalating lump sum. Override any single year manually if you want it to diverge.
A41: SEED START POINT (pilot actuals — update monthly)
...

Sheet Monthly Model
A1: Month # | B1: Calendar Month | C1: Year | D1: Growth Phase | E1: SOM Ceiling | F1: Monthly Growth Rate | G1: Gross New Logos | H1: Churned Logos | I1: Cumulative Logos | J1: Seasonal Active % | K1: Effective Paying Vessels | L1: Blended Price (EUR) | M1: MRR (EUR) | N1: Monthly Opex (EUR) | O1: Gross Profit (EUR) | P1: Net Cash Flow (EUR) | Q1: Months Since Caribbean Launch | R1: Caribbean Growth Phase | S1: Caribbean SOM Ceiling | T1: Caribbean Monthly Growth Rate | U1: Caribbean Gross New Logos | V1: Caribbean Churned Logos | W1: Caribbean Cumulative Logos | X1: Caribbean Seasonal Active % | Y1: Caribbean Effective Paying Vessels | Z1: Caribbean Blended Price (EUR) | AA1: Caribbean MRR (EUR) | AB1: Caribbean Incremental Opex (EUR) | AC1: Caribbean Gross Profit (EUR) | AD1: Total Cumulative Logos (Med + Caribbean) | AE1: Total MRR (EUR) | AF1: Total Opex (EUR) | AG1: Total Gross Profit (EUR) | AH1: Total Net Cash Flow (EUR) | AI1: Total Cumulative Logos MoM growth % | AJ1: AI Token Cost — Company-wide (EUR) | AK1: Sales/BD Hire Incremental Opex (EUR) | AL1: Caribbean Regional Hire Opex (EUR)
A2: 1 | B2: Aug 2026 | C2: =IF(A2<=12,1,IF(A2<=24,2,IF(A2<=36,3,4))) -> 1 | D2: =IF(A2<=6,"P1: Pilot->Seed",IF(A2<=18,"P2: Scale/Series A",IF(A2<=36,"P3: Post-Series A","P4: Maturity"))) -> P1: Pilot->Seed | E2: =IF(C2=1,Assumptions!$B$5,IF(C2=2,Assumptions!$B$6,IF(C2=3,Assumptions!$B$7,Assumptions!$B$8))) -> 1200 | F2: =IF(A2<=6,Assumptions!$B$14,IF(A2<=18,Assumptions!$B$15,IF(A2<=36,Assumptions!$B$16,Assumptions!$B$17))) -> 0.35 | G2: =ROUND(MAX(Assumptions!$B$42,1)*F2,0) -> 1 | H2: =ROUND(Assumptions!$B$42*Assumptions!$B$18,0) -> 0 | I2: =MIN(Assumptions!$B$42+G2-H2,E2) -> 3 | J2: =Assumptions!$B$27 -> 1 | K2: =I2*J2 -> 3 | L2: =Assumptions!$B$10*(1-Assumptions!$B$12)+Assumptions!$B$11*Assumptions!$B$12 -> 46.06 | M2: =K2*L2 -> 138.18 | N2: =((IF(A2<=Assumptions!$B$91,Assumptions!$B$90,IF(A2>=Assumptions!$B$92,1,Assumptions!$B$90+(1-Assumptions!$B$90)*(A2-Assumptions!$B$91)/(Assumptions!$B$92-Assumptions!$B$91))))*Assumptions!$B$81*Assumptions!$B$75+Assumptions!$B$82)*(1+Assumptions!$B$83)/12 -> 3354.1667 | O2: =M2*Assumptions!$B$33 -> 117.453 | P2: =O2-N2 -> -3236.7137 | Q2: =IF(A2>=Assumptions!$B$45,A2-Assumptions!$B$45+1,"") | R2: =IF(Q2="","Not yet launched",IF(Q2<=6,"CP1: Launch",IF(Q2<=18,"CP2: Scale",IF(Q2<=36,"CP3: Mature","CP4: Steady")))) -> Not yet launched | S2: =IF(Q2="",0,Assumptions!$B$46) -> 0 | T2: =IF(Q2="",0,IF(Q2<=6,Assumptions!$B$14,IF(Q2<=18,Assumptions!$B$15,IF(Q2<=36,Assumptions!$B$16,Assumptions!$B$17)))) -> 0 | U2: =IF(Q2="",0,IF(Q2=1,Assumptions!$B$65,ROUND(MAX(0,1)*T2,0))) -> 0 | V2: =IF(Q2="",0,ROUND(0*Assumptions!$B$49,0)) -> 0 | W2: =IF(Q2="",0,MIN(0+U2-V2,S2)) -> 0 | X2: =IF(Q2="",0,Assumptions!$B$59) -> 0 | Y2: =W2*X2 -> 0 | Z2: =L2 -> 46.06 | AA2: =Y2*Z2 -> 0 | AB2: =IF(A2=Assumptions!$B$45,Assumptions!$B$47+Assumptions!$B$48,IF(A2>Assumptions!$B$45,Assumptions!$B$47,0)) -> 0 | AC2: =AA2*Assumptions!$B$33 -> 0 | AD2: =I2+W2 -> 3 | AE2: =M2+AA2 -> 138.18 | AF2: =N2+AB2+AJ2+AK2+AL2+Assumptions!$B$68 -> 3672.4863 | AG2: =O2+AC2 -> 117.453 | AH2: =AG2-AF2 -> -3555.0333 | AJ2: =MAX(Assumptions!$B$71,Assumptions!$B$69*0.5^(A2/Assumptions!$B$70))+Assumptions!$B$72*(K2+Y2) -> 268.31962 | AK2: =IF(AND(Assumptions!$B$76=1,A2>=Assumptions!$B$77),Assumptions!$B$78/12,0) -> 0 | AL2: =IF(AND(Assumptions!$B$86=1,Q2<>""),Assumptions!$B$87/12,0) -> 0
A3: 2 | B3: Sep 2026 | C3: =IF(A3<=12,1,IF(A3<=24,2,IF(A3<=36,3,4))) -> 1 | D3: =IF(A3<=6,"P1: Pilot->Seed",IF(A3<=18,"P2: Scale/Series A",IF(A3<=36,"P3: Post-Series A","P4: Maturity"))) -> P1: Pilot->Seed | E3: =IF(C3=1,Assumptions!$B$5,IF(C3=2,Assumptions!$B$6,IF(C3=3,Assumptions!$B$7,Assumptions!$B$8))) -> 1200 | F3: =IF(A3<=6,Assumptions!$B$14,IF(A3<=18,Assumptions!$B$15,IF(A3<=36,Assumptions!$B$16,Assumptions!$B$17))) -> 0.35 | G3: =ROUND(MAX(I2,1)*F3,0) -> 1 | H3: =ROUND(I2*Assumptions!$B$18,0) -> 0 | I3: =MIN(I2+G3-H3,E3) -> 4 | J3: =Assumptions!$B$28 -> 1 | K3: =I3*J3 -> 4 | L3: =Assumptions!$B$10*(1-Assumptions!$B$12)+Assumptions!$B$11*Assumptions!$B$12 -> 46.06 | M3: =K3*L3 -> 184.24 | N3: =((IF(A3<=Assumptions!$B$91,Assumptions!$B$90,IF(A3>=Assumptions!$B$92,1,Assumptions!$B$90+(1-Assumptions!$B$90)*(A3-Assumptions!$B$91)/(Assumptions!$B$92-Assumptions!$B$91))))*Assumptions!$B$81*Assumptions!$B$75+Assumptions!$B$82)*(1+Assumptions!$B$83)/12 -> 3354.1667 | O3: =M3*Assumptions!$B$33 -> 156.604 | P3: =O3-N3 -> -3197.5627 | Q3: =IF(A3>=Assumptions!$B$45,A3-Assumptions!$B$45+1,"") | R3: =IF(Q3="","Not yet launched",IF(Q3<=6,"CP1: Launch",IF(Q3<=18,"CP2: Scale",IF(Q3<=36,"CP3: Mature","CP4: Steady")))) -> Not yet launched | S3: =IF(Q3="",0,Assumptions!$B$46) -> 0 | T3: =IF(Q3="",0,IF(Q3<=6,Assumptions!$B$14,IF(Q3<=18,Assumptions!$B$15,IF(Q3<=36,Assumptions!$B$16,Assumptions!$B$17)))) -> 0 | U3: =IF(Q3="",0,IF(Q3=1,Assumptions!$B$65,ROUND(MAX(W2,1)*T3,0))) -> 0 | V3: =IF(Q3="",0,ROUND(W2*Assumptions!$B$49,0)) -> 0 | W3: =IF(Q3="",0,MIN(W2+U3-V3,S3)) -> 0 | X3: =IF(Q3="",0,Assumptions!$B$60) -> 0 | Y3: =W3*X3 -> 0 | Z3: =L3 -> 46.06 | AA3: =Y3*Z3 -> 0 | AB3: =IF(A3=Assumptions!$B$45,Assumptions!$B$47+Assumptions!$B$48,IF(A3>Assumptions!$B$45,Assumptions!$B$47,0)) -> 0 | AC3: =AA3*Assumptions!$B$33 -> 0 | AD3: =I3+W3 -> 4 | AE3: =M3+AA3 -> 184.24 | AF3: =N3+AB3+AJ3+AK3+AL3+Assumptions!$B$68 -> 3643.6768 | AG3: =O3+AC3 -> 156.604 | AH3: =AG3-AF3 -> -3487.0728 | AI3: =IFERROR((AD3-AD2)/AD2,"") -> 0.33333333 | AJ3: =MAX(Assumptions!$B$71,Assumptions!$B$69*0.5^(A3/Assumptions!$B$70))+Assumptions!$B$72*(K3+Y3) -> 239.51016 | AK3: =IF(AND(Assumptions!$B$76=1,A3>=Assumptions!$B$77),Assumptions!$B$78/12,0) -> 0 | AL3: =IF(AND(Assumptions!$B$86=1,Q3<>""),Assumptions!$B$87/12,0) -> 0
A4: 3 | B4: Oct 2026 | C4: =IF(A4<=12,1,IF(A4<=24,2,IF(A4<=36,3,4))) -> 1 | D4: =IF(A4<=6,"P1: Pilot->Seed",IF(A4<=18,"P2: Scale/Series A",IF(A4<=36,"P3: Post-Series A","P4: Maturity"))) -> P1: Pilot->Seed | E4: =IF(C4=1,Assumptions!$B$5,IF(C4=2,Assumptions!$B$6,IF(C4=3,Assumptions!$B$7,Assumptions!$B$8))) -> 1200 | F4: =IF(A4<=6,Assumptions!$B$14,IF(A4<=18,Assumptions!$B$15,IF(A4<=36,Assumptions!$B$16,Assumptions!$B$17))) -> 0.35 | G4: =ROUND(MAX(I3,1)*F4,0) -> 1 | H4: =ROUND(I3*Assumptions!$B$18,0) -> 0 | I4: =MIN(I3+G4-H4,E4) -> 5 | J4: =Assumptions!$B$29 -> 0.85 | K4: =I4*J4 -> 4.25 | L4: =Assumptions!$B$10*(1-Assumptions!$B$12)+Assumptions!$B$11*Assumptions!$B$12 -> 46.06 | M4: =K4*L4 -> 195.755 | N4: =((IF(A4<=Assumptions!$B$91,Assumptions!$B$90,IF(A4>=Assumptions!$B$92,1,Assumptions!$B$90+(1-Assumptions!$B$90)*(A4-Assumptions!$B$91)/(Assumptions!$B$92-Assumptions!$B$91))))*Assumptions!$B$81*Assumptions!$B$75+Assumptions!$B$82)*(1+Assumptions!$B$83)/12 -> 3354.1667 | O4: =M4*Assumptions!$B$33 -> 166.39175 | P4: =O4-N4 -> -3187.7749 | Q4: =IF(A4>=Assumptions!$B$45,A4-Assumptions!$B$45+1,"") | R4: =IF(Q4="","Not yet launched",IF(Q4<=6,"CP1: Launch",IF(Q4<=18,"CP2: Scale",IF(Q4<=36,"CP3: Mature","CP4: Steady")))) -> Not yet launched | S4: =IF(Q4="",0,Assumptions!$B$46) -> 0 | T4: =IF(Q4="",0,IF(Q4<=6,Assumptions!$B$14,IF(Q4<=18,Assumptions!$B$15,IF(Q4<=36,Assumptions!$B$16,Assumptions!$B$17)))) -> 0 | U4: =IF(Q4="",0,IF(Q4=1,Assumptions!$B$65,ROUND(MAX(W3,1)*T4,0))) -> 0 | V4: =IF(Q4="",0,ROUND(W3*Assumptions!$B$49,0)) -> 0 | W4: =IF(Q4="",0,MIN(W3+U4-V4,S4)) -> 0 | X4: =IF(Q4="",0,Assumptions!$B$61) -> 0 | Y4: =W4*X4 -> 0 | Z4: =L4 -> 46.06 | AA4: =Y4*Z4 -> 0 | AB4: =IF(A4=Assumptions!$B$45,Assumptions!$B$47+Assumptions!$B$48,IF(A4>Assumptions!$B$45,Assumptions!$B$47,0)) -> 0 | AC4: =AA4*Assumptions!$B$33 -> 0 | AD4: =I4+W4 -> 5 | AE4: =M4+AA4 -> 195.755 | AF4: =N4+AB4+AJ4+AK4+AL4+Assumptions!$B$68 -> 3617.7862 | AG4: =O4+AC4 -> 166.39175 | AH4: =AG4-AF4 -> -3451.3945 | AI4: =IFERROR((AD4-AD3)/AD3,"") -> 0.25 | AJ4: =MAX(Assumptions!$B$71,Assumptions!$B$69*0.5^(A4/Assumptions!$B$70))+Assumptions!$B$72*(K4+Y4) -> 213.61953 | AK4: =IF(AND(Assumptions!$B$76=1,A4>=Assumptions!$B$77),Assumptions!$B$78/12,0) -> 0 | AL4: =IF(AND(Assumptions!$B$86=1,Q4<>""),Assumptions!$B$87/12,0) -> 0
A5: 4 | B5: Nov 2026 | C5: =IF(A5<=12,1,IF(A5<=24,2,IF(A5<=36,3,4))) -> 1 | D5: =IF(A5<=6,"P1: Pilot->Seed",IF(A5<=18,"P2: Scale/Series A",IF(A5<=36,"P3: Post-Series A","P4: Maturity"))) -> P1: Pilot->Seed | E5: =IF(C5=1,Assumptions!$B$5,IF(C5=2,Assumptions!$B$6,IF(C5=3,Assumptions!$B$7,Assumptions!$B$8))) -> 1200 | F5: =IF(A5<=6,Assumptions!$B$14,IF(A5<=18,Assumptions!$B$15,IF(A5<=36,Assumptions!$B$16,Assumptions!$B$17))) -> 0.35 | G5: =ROUND(MAX(I4,1)*F5,0) -> 2 | H5: =ROUND(I4*Assumptions!$B$18,0) -> 0 | I5: =MIN(I4+G5-H5,E5) -> 7 | J5: =Assumptions!$B$30 -> 0.45 | K5: =I5*J5 -> 3.15 | L5: =Assumptions!$B$10*(1-Assumptions!$B$12)+Assumptions!$B$11*Assumptions!$B$12 -> 46.06 | M5: =K5*L5 -> 145.089 | N5: =((IF(A5<=Assumptions!$B$91,Assumptions!$B$90,IF(A5>=Assumptions!$B$92,1,Assumptions!$B$90+(1-Assumptions!$B$90)*(A5-Assumptions!$B$91)/(Assumptions!$B$92-Assumptions!$B$91))))*Assumptions!$B$81*Assumptions!$B$75+Assumptions!$B$82)*(1+Assumptions!$B$83)/12 -> 3354.1667 | O5: =M5*Assumptions!$B$33 -> 123.32565 | P5: =O5-N5 -> -3230.841 | Q5: =IF(A5>=Assumptions!$B$45,A5-Assumptions!$B$45+1,"") | R5: =IF(Q5="","Not yet launched",IF(Q5<=6,"CP1: Launch",IF(Q5<=18,"CP2: Scale",IF(Q5<=36,"CP3: Mature","CP4: Steady")))) -> Not yet launched | S5: =IF(Q5="",0,Assumptions!$B$46) -> 0 | T5: =IF(Q5="",0,IF(Q5<=6,Assumptions!$B$14,IF(Q5<=18,Assumptions!$B$15,IF(Q5<=36,Assumptions!$B$16,Assumptions!$B$17)))) -> 0 | U5: =IF(Q5="",0,IF(Q5=1,Assumptions!$B$65,ROUND(MAX(W4,1)*T5,0))) -> 0 | V5: =IF(Q5="",0,ROUND(W4*Assumptions!$B$49,0)) -> 0 | W5: =IF(Q5="",0,MIN(W4+U5-V5,S5)) -> 0 | X5: =IF(Q5="",0,Assumptions!$B$62) -> 0 | Y5: =W5*X5 -> 0 | Z5: =L5 -> 46.06 | AA5: =Y5*Z5 -> 0 | AB5: =IF(A5=Assumptions!$B$45,Assumptions!$B$47+Assumptions!$B$48,IF(A5>Assumptions!$B$45,Assumptions!$B$47,0)) -> 0 | AC5: =AA5*Assumptions!$B$33 -> 0 | AD5: =I5+W5 -> 7 | AE5: =M5+AA5 -> 145.089 | AF5: =N5+AB5+AJ5+AK5+AL5+Assumptions!$B$68 -> 3594.2573 | AG5: =O5+AC5 -> 123.32565 | AH5: =AG5-AF5 -> -3470.9317 | AI5: =IFERROR((AD5-AD4)/AD4,"") -> 0.4 | AJ5: =MAX(Assumptions!$B$71,Assumptions!$B$69*0.5^(A5/Assumptions!$B$70))+Assumptions!$B$72*(K5+Y5) -> 190.09066 | AK5: =IF(AND(Assumptions!$B$76=1,A5>=Assumptions!$B$77),Assumptions!$B$78/12,0) -> 0 | AL5: =IF(AND(Assumptions!$B$86=1,Q5<>""),Assumptions!$B$87/12,0) -> 0
A6: 5 | B6: Dec 2026 | C6: =IF(A6<=12,1,IF(A6<=24,2,IF(A6<=36,3,4))) -> 1 | D6: =IF(A6<=6,"P1: Pilot->Seed",IF(A6<=18,"P2: Scale/Series A",IF(A6<=36,"P3: Post-Series A","P4: Maturity"))) -> P1: Pilot->Seed | E6: =IF(C6=1,Assumptions!$B$5,IF(C6=2,Assumptions!$B$6,IF(C6=3,Assumptions!$B$7,Assumptions!$B$8))) -> 1200 | F6: =IF(A6<=6,Assumptions!$B$14,IF(A6<=18,Assumptions!$B$15,IF(A6<=36,Assumptions!$B$16,Assumptions!$B$17))) -> 0.35 | G6: =ROUND(MAX(I5,1)*F6,0) -> 2 | H6: =ROUND(I5*Assumptions!$B$18,0) -> 0 | I6: =MIN(I5+G6-H6,E6) -> 9 | J6: =Assumptions!$B$31 -> 0.35 | K6: =I6*J6 -> 3.15 | L6: =Assumptions!$B$10*(1-Assumptions!$B$12)+Assumptions!$B$11*Assumptions!$B$12 -> 46.06 | M6: =K6*L6 -> 145.089 | N6: =((IF(A6<=Assumptions!$B$91,Assumptions!$B$90,IF(A6>=Assumptions!$B$92,1,Assumptions!$B$90+(1-Assumptions!$B$90)*(A6-Assumptions!$B$91)/(Assumptions!$B$92-Assumptions!$B$91))))*Assumptions!$B$81*Assumptions!$B$75+Assumptions!$B$82)*(1+Assumptions!$B$83)/12 -> 3354.1667 | O6: =M6*Assumptions!$B$33 -> 123.32565 | P6: =O6-N6 -> -3230.841 | Q6: =IF(A6>=Assumptions!$B$45,A6-Assumptions!$B$45+1,"") | R6: =IF(Q6="","Not yet launched",IF(Q6<=6,"CP1: Launch",IF(Q6<=18,"CP2: Scale",IF(Q6<=36,"CP3: Mature","CP4: Steady")))) -> Not yet launched | S6: =IF(Q6="",0,Assumptions!$B$46) -> 0 | T6: =IF(Q6="",0,IF(Q6<=6,Assumptions!$B$14,IF(Q6<=18,Assumptions!$B$15,IF(Q6<=36,Assumptions!$B$16,Assumptions!$B$17)))) -> 0 | U6: =IF(Q6="",0,IF(Q6=1,Assumptions!$B$65,ROUND(MAX(W5,1)*T6,0))) -> 0 | V6: =IF(Q6="",0,ROUND(W5*Assumptions!$B$49,0)) -> 0 | W6: =IF(Q6="",0,MIN(W5+U6-V6,S6)) -> 0 | X6: =IF(Q6="",0,Assumptions!$B$63) -> 0 | Y6: =W6*X6 -> 0 | Z6: =L6 -> 46.06 | AA6: =Y6*Z6 -> 0 | AB6: =IF(A6=Assumptions!$B$45,Assumptions!$B$47+Assumptions!$B$48,IF(A6>Assumptions!$B$45,Assumptions!$B$47,0)) -> 0 | AC6: =AA6*Assumptions!$B$33 -> 0 | AD6: =I6+W6 -> 9 | AE6: =M6+AA6 -> 145.089 | AF6: =N6+AB6+AJ6+AK6+AL6+Assumptions!$B$68 -> 3573.6385 | AG6: =O6+AC6 -> 123.32565 | AH6: =AG6-AF6 -> -3450.3128 | AI6: =IFERROR((AD6-AD5)/AD5,"") -> 0.28571429 | AJ6: =MAX(Assumptions!$B$71,Assumptions!$B$69*0.5^(A6/Assumptions!$B$70))+Assumptions!$B$72*(K6+Y6) -> 169.47181 | AK6: =IF(AND(Assumptions!$B$76=1,A6>=Assumptions!$B$77),Assumptions!$B$78/12,0) -> 0 | AL6: =IF(AND(Assumptions!$B$86=1,Q6<>""),Assumptions!$B$87/12,0) -> 0
A7: 6 | B7: Jan 2027 | C7: =IF(A7<=12,1,IF(A7<=24,2,IF(A7<=36,3,4))) -> 1 | D7: =IF(A7<=6,"P1: Pilot->Seed",IF(A7<=18,"P2: Scale/Series A",IF(A7<=36,"P3: Post-Series A","P4: Maturity"))) -> P1: Pilot->Seed | E7: =IF(C7=1,Assumptions!$B$5,IF(C7=2,Assumptions!$B$6,IF(C7=3,Assumptions!$B$7,Assumptions!$B$8))) -> 1200 | F7: =IF(A7<=6,Assumptions!$B$14,IF(A7<=18,Assumptions!$B$15,IF(A7<=36,Assumptions!$B$16,Assumptions!$B$17))) -> 0.35 | G7: =ROUND(MAX(I6,1)*F7,0) -> 3 | H7: =ROUND(I6*Assumptions!$B$18,0) -> 0 | I7: =MIN(I6+G7-H7,E7) -> 12 | J7: =Assumptions!$B$20 -> 0.35 | K7: =I7*J7 -> 4.2 | L7: =Assumptions!$B$10*(1-Assumptions!$B$12)+Assumptions!$B$11*Assumptions!$B$12 -> 46.06 | M7: =K7*L7 -> 193.452 | N7: =((IF(A7<=Assumptions!$B$91,Assumptions!$B$90,IF(A7>=Assumptions!$B$92,1,Assumptions!$B$90+(1-Assumptions!$B$90)*(A7-Assumptions!$B$91)/(Assumptions!$B$92-Assumptions!$B$91))))*Assumptions!$B$81*Assumptions!$B$75+Assumptions!$B$82)*(1+Assumptions!$B$83)/12 -> 3354.1667 | O7: =M7*Assumptions!$B$33 -> 164.4342 | P7: =O7-N7 -> -3189.7325 | Q7: =IF(A7>=Assumptions!$B$45,A7-Assumptions!$B$45+1,"") | R7: =IF(Q7="","Not yet launched",IF(Q7<=6,"CP1: Launch",IF(Q7<=18,"CP2: Scale",IF(Q7<=36,"CP3: Mature","CP4: Steady")))) -> Not yet launched | S7: =IF(Q7="",0,Assumptions!$B$46) -> 0 | T7: =IF(Q7="",0,IF(Q7<=6,Assumptions!$B$14,IF(Q7<=18,Assumptions!$B$15,IF(Q7<=36,Assumptions!$B$16,Assumptions!$B$17)))) -> 0 | U7: =IF(Q7="",0,IF(Q7=1,Assumptions!$B$65,ROUND(MAX(W6,1)*T7,0))) -> 0 | V7: =IF(Q7="",0,ROUND(W6*Assumptions!$B$49,0)) -> 0 | W7: =IF(Q7="",0,MIN(W6+U7-V7,S7)) -> 0 | X7: =IF(Q7="",0,Assumptions!$B$52) -> 0 | Y7: =W7*X7 -> 0 | Z7: =L7 -> 46.06 | AA7: =Y7*Z7 -> 0 | AB7: =IF(A7=Assumptions!$B$45,Assumptions!$B$47+Assumptions!$B$48,IF(A7>Assumptions!$B$45,Assumptions!$B$47,0)) -> 0 | AC7: =AA7*Assumptions!$B$33 -> 0 | AD7: =I7+W7 -> 12 | AE7: =M7+AA7 -> 193.452 | AF7: =N7+AB7+AJ7+AK7+AL7+Assumptions!$B$68 -> 3555.6367 | AG7: =O7+AC7 -> 164.4342 | AH7: =AG7-AF7 -> -3391.2025 | AI7: =IFERROR((AD7-AD6)/AD6,"") -> 0.33333333 | AJ7: =MAX(Assumptions!$B$71,Assumptions!$B$69*0.5^(A7/Assumptions!$B$70))+Assumptions!$B$72*(K7+Y7) -> 151.47 | AK7: =IF(AND(Assumptions!$B$76=1,A7>=Assumptions!$B$77),Assumptions!$B$78/12,0) -> 0 | AL7: =IF(AND(Assumptions!$B$86=1,Q7<>""),Assumptions!$B$87/12,0) -> 0
A8: 7 | B8: Feb 2027 | C8: =IF(A8<=12,1,IF(A8<=24,2,IF(A8<=36,3,4))) -> 1 | D8: =IF(A8<=6,"P1: Pilot->Seed",IF(A8<=18,"P2: Scale/Series A",IF(A8<=36,"P3: Post-Series A","P4: Maturity"))) -> P2: Scale/Series A | E8: =IF(C8=1,Assumptions!$B$5,IF(C8=2,Assumptions!$B$6,IF(C8=3,Assumptions!$B$7,Assumptions!$B$8))) -> 1200 | F8: =IF(A8<=6,Assumptions!$B$14,IF(A8<=18,Assumptions!$B$15,IF(A8<=36,Assumptions!$B$16,Assumptions!$B$17))) -> 0.14 | G8: =ROUND(MAX(I7,1)*F8,0) -> 2 | H8: =ROUND(I7*Assumptions!$B$18,0) -> 0 | I8: =MIN(I7+G8-H8,E8) -> 14 | J8: =Assumptions!$B$21 -> 0.35 | K8: =I8*J8 -> 4.9 | L8: =Assumptions!$B$10*(1-Assumptions!$B$12)+Assumptions!$B$11*Assumptions!$B$12 -> 46.06 | M8: =K8*L8 -> 225.694 | N8: =((IF(A8<=Assumptions!$B$91,Assumptions!$B$90,IF(A8>=Assumptions!$B$92,1,Assumptions!$B$90+(1-Assumptions!$B$90)*(A8-Assumptions!$B$91)/(Assumptions!$B$92-Assumptions!$B$91))))*Assumptions!$B$81*Assumptions!$B$75+Assumptions!$B$82)*(1+Assumptions!$B$83)/12 -> 3354.1667 | O8: =M8*Assumptions!$B$33 -> 191.8399 | P8: =O8-N8 -> -3162.3268 | Q8: =IF(A8>=Assumptions!$B$45,A8-Assumptions!$B$45+1,"") | R8: =IF(Q8="","Not yet launched",IF(Q8<=6,"CP1: Launch",IF(Q8<=18,"CP2: Scale",IF(Q8<=36,"CP3: Mature","CP4: Steady")))) -> Not yet launched | S8: =IF(Q8="",0,Assumptions!$B$46) -> 0 | T8: =IF(Q8="",0,IF(Q8<=6,Assumptions!$B$14,IF(Q8<=18,Assumptions!$B$15,IF(Q8<=36,Assumptions!$B$16,Assumptions!$B$17)))) -> 0 | U8: =IF(Q8="",0,IF(Q8=1,Assumptions!$B$65,ROUND(MAX(W7,1)*T8,0))) -> 0 | V8: =IF(Q8="",0,ROUND(W7*Assumptions!$B$49,0)) -> 0 | W8: =IF(Q8="",0,MIN(W7+U8-V8,S8)) -> 0 | X8: =IF(Q8="",0,Assumptions!$B$53) -> 0 | Y8: =W8*X8 -> 0 | Z8: =L8 -> 46.06 | AA8: =Y8*Z8 -> 0 | AB8: =IF(A8=Assumptions!$B$45,Assumptions!$B$47+Assumptions!$B$48,IF(A8>Assumptions!$B$45,Assumptions!$B$47,0)) -> 0 | AC8: =AA8*Assumptions!$B$33 -> 0 | AD8: =I8+W8 -> 14 | AE8: =M8+AA8 -> 225.694 | AF8: =N8+AB8+AJ8+AK8+AL8+Assumptions!$B$68 -> 3539.5165 | AG8: =O8+AC8 -> 191.8399 | AH8: =AG8-AF8 -> -3347.6766 | AI8: =IFERROR((AD8-AD7)/AD7,"") -> 0.16666667 | AJ8: =MAX(Assumptions!$B$71,Assumptions!$B$69*0.5^(A8/Assumptions!$B$70))+Assumptions!$B$72*(K8+Y8) -> 135.34981 | AK8: =IF(AND(Assumptions!$B$76=1,A8>=Assumptions!$B$77),Assumptions!$B$78/12,0) -> 0 | AL8: =IF(AND(Assumptions!$B$86=1,Q8<>""),Assumptions!$B$87/12,0) -> 0
A9: 8 | B9: Mar 2027 | C9: =IF(A9<=12,1,IF(A9<=24,2,IF(A9<=36,3,4))) -> 1 | D9: =IF(A9<=6,"P1: Pilot->Seed",IF(A9<=18,"P2: Scale/Series A",IF(A9<=36,"P3: Post-Series A","P4: Maturity"))) -> P2: Scale/Series A | E9: =IF(C9=1,Assumptions!$B$5,IF(C9=2,Assumptions!$B$6,IF(C9=3,Assumptions!$B$7,Assumptions!$B$8))) -> 1200 | F9: =IF(A9<=6,Assumptions!$B$14,IF(A9<=18,Assumptions!$B$15,IF(A9<=36,Assumptions!$B$16,Assumptions!$B$17))) -> 0.14 | G9: =ROUND(MAX(I8,1)*F9,0) -> 2 | H9: =ROUND(I8*Assumptions!$B$18,0) -> 0 | I9: =MIN(I8+G9-H9,E9) -> 16 | J9: =Assumptions!$B$22 -> 0.55 | K9: =I9*J9 -> 8.8 | L9: =Assumptions!$B$10*(1-Assumptions!$B$12)+Assumptions!$B$11*Assumptions!$B$12 -> 46.06 | M9: =K9*L9 -> 405.328 | N9: =((IF(A9<=Assumptions!$B$91,Assumptions!$B$90,IF(A9>=Assumptions!$B$92,1,Assumptions!$B$90+(1-Assumptions!$B$90)*(A9-Assumptions!$B$91)/(Assumptions!$B$92-Assumptions!$B$91))))*Assumptions!$B$81*Assumptions!$B$75+Assumptions!$B$82)*(1+Assumptions!$B$83)/12 -> 5430.5556 | O9: =M9*Assumptions!$B$33 -> 344.5288 | P9: =O9-N9 -> -5086.0268 | Q9: =IF(A9>=Assumptions!$B$45,A9-Assumptions!$B$45+1,"") | R9: =IF(Q9="","Not yet launched",IF(Q9<=6,"CP1: Launch",IF(Q9<=18,"CP2: Scale",IF(Q9<=36,"CP3: Mature","CP4: Steady")))) -> Not yet launched | S9: =IF(Q9="",0,Assumptions!$B$46) -> 0 | T9: =IF(Q9="",0,IF(Q9<=6,Assumptions!$B$14,IF(Q9<=18,Assumptions!$B$15,IF(Q9<=36,Assumptions!$B$16,Assumptions!$B$17)))) -> 0 | U9: =IF(Q9="",0,IF(Q9=1,Assumptions!$B$65,ROUND(MAX(W8,1)*T9,0))) -> 0 | V9: =IF(Q9="",0,ROUND(W8*Assumptions!$B$49,0)) -> 0 | W9: =IF(Q9="",0,MIN(W8+U9-V9,S9)) -> 0 | X9: =IF(Q9="",0,Assumptions!$B$54) -> 0 | Y9: =W9*X9 -> 0 | Z9: =L9 -> 46.06 | AA9: =Y9*Z9 -> 0 | AB9: =IF(A9=Assumptions!$B$45,Assumptions!$B$47+Assumptions!$B$48,IF(A9>Assumptions!$B$45,Assumptions!$B$47,0)) -> 0 | AC9: =AA9*Assumptions!$B$33 -> 0 | AD9: =I9+W9 -> 16 | AE9: =M9+AA9 -> 405.328 | AF9: =N9+AB9+AJ9+AK9+AL9+Assumptions!$B$68 -> 5602.6906 | AG9: =O9+AC9 -> 344.5288 | AH9: =AG9-AF9 -> -5258.1618 | AI9: =IFERROR((AD9-AD8)/AD8,"") -> 0.14285714 | AJ9: =MAX(Assumptions!$B$71,Assumptions!$B$69*0.5^(A9/Assumptions!$B$70))+Assumptions!$B$72*(K9+Y9) -> 122.13508 | AK9: =IF(AND(Assumptions!$B$76=1,A9>=Assumptions!$B$77),Assumptions!$B$78/12,0) -> 0 | AL9: =IF(AND(Assumptions!$B$86=1,Q9<>""),Assumptions!$B$87/12,0) -> 0
A10: 9 | B10: Apr 2027 | C10: =IF(A10<=12,1,IF(A10<=24,2,IF(A10<=36,3,4))) -> 1 | D10: =IF(A10<=6,"P1: Pilot->Seed",IF(A10<=18,"P2: Scale/Series A",IF(A10<=36,"P3: Post-Series A","P4: Maturity"))) -> P2: Scale/Series A | E10: =IF(C10=1,Assumptions!$B$5,IF(C10=2,Assumptions!$B$6,IF(C10=3,Assumptions!$B$7,Assumptions!$B$8))) -> 1200 | F10: =IF(A10<=6,Assumptions!$B$14,IF(A10<=18,Assumptions!$B$15,IF(A10<=36,Assumptions!$B$16,Assumptions!$B$17))) -> 0.14 | G10: =ROUND(MAX(I9,1)*F10,0) -> 2 | H10: =ROUND(I9*Assumptions!$B$18,0) -> 0 | I10: =MIN(I9+G10-H10,E10) -> 18 | J10: =Assumptions!$B$23 -> 0.85 | K10: =I10*J10 -> 15.3 | L10: =Assumptions!$B$10*(1-Assumptions!$B$12)+Assumptions!$B$11*Assumptions!$B$12 -> 46.06 | M10: =K10*L10 -> 704.718 | N10: =((IF(A10<=Assumptions!$B$91,Assumptions!$B$90,IF(A10>=Assumptions!$B$92,1,Assumptions!$B$90+(1-Assumptions!$B$90)*(A10-Assumptions!$B$91)/(Assumptions!$B$92-Assumptions!$B$91))))*Assumptions!$B$81*Assumptions!$B$75+Assumptions!$B$82)*(1+Assumptions!$B$83)/12 -> 7506.9444 | O10: =M10*Assumptions!$B$33 -> 599.0103 | P10: =O10-N10 -> -6907.9341 | Q10: =IF(A10>=Assumptions!$B$45,A10-Assumptions!$B$45+1,"") | R10: =IF(Q10="","Not yet launched",IF(Q10<=6,"CP1: Launch",IF(Q10<=18,"CP2: Scale",IF(Q10<=36,"CP3: Mature","CP4: Steady")))) -> Not yet launched | S10: =IF(Q10="",0,Assumptions!$B$46) -> 0 | T10: =IF(Q10="",0,IF(Q10<=6,Assumptions!$B$14,IF(Q10<=18,Assumptions!$B$15,IF(Q10<=36,Assumptions!$B$16,Assumptions!$B$17)))) -> 0 | U10: =IF(Q10="",0,IF(Q10=1,Assumptions!$B$65,ROUND(MAX(W9,1)*T10,0))) -> 0 | V10: =IF(Q10="",0,ROUND(W9*Assumptions!$B$49,0)) -> 0 | W10: =IF(Q10="",0,MIN(W9+U10-V10,S10)) -> 0 | X10: =IF(Q10="",0,Assumptions!$B$55) -> 0 | Y10: =W10*X10 -> 0 | Z10: =L10 -> 46.06 | AA10: =Y10*Z10 -> 0 | AB10: =IF(A10=Assumptions!$B$45,Assumptions!$B$47+Assumptions!$B$48,IF(A10>Assumptions!$B$45,Assumptions!$B$47,0)) -> 0 | AC10: =AA10*Assumptions!$B$33 -> 0 | AD10: =I10+W10 -> 18 | AE10: =M10+AA10 -> 704.718 | AF10: =N10+AB10+AJ10+AK10+AL10+Assumptions!$B$68 -> 7668.3655 | AG10: =O10+AC10 -> 599.0103 | AH10: =AG10-AF10 -> -7069.3552 | AI10: =IFERROR((AD10-AD9)/AD9,"") -> 0.125 | AJ10: =MAX(Assumptions!$B$71,Assumptions!$B$69*0.5^(A10/Assumptions!$B$70))+Assumptions!$B$72*(K10+Y10) -> 111.42102 | AK10: =IF(AND(Assumptions!$B$76=1,A10>=Assumptions!$B$77),Assumptions!$B$78/12,0) -> 0 | AL10: =IF(AND(Assumptions!$B$86=1,Q10<>""),Assumptions!$B$87/12,0) -> 0
A11: 10 | B11: May 2027 | C11: =IF(A11<=12,1,IF(A11<=24,2,IF(A11<=36,3,4))) -> 1 | D11: =IF(A11<=6,"P1: Pilot->Seed",IF(A11<=18,"P2: Scale/Series A",IF(A11<=36,"P3: Post-Series A","P4: Maturity"))) -> P2: Scale/Series A | E11: =IF(C11=1,Assumptions!$B$5,IF(C11=2,Assumptions!$B$6,IF(C11=3,Assumptions!$B$7,Assumptions!$B$8))) -> 1200 | F11: =IF(A11<=6,Assumptions!$B$14,IF(A11<=18,Assumptions!$B$15,IF(A11<=36,Assumptions!$B$16,Assumptions!$B$17))) -> 0.14 | G11: =ROUND(MAX(I10,1)*F11,0) -> 3 | H11: =ROUND(I10*Assumptions!$B$18,0) -> 0 | I11: =MIN(I10+G11-H11,E11) -> 21 | J11: =Assumptions!$B$24 -> 1 | K11: =I11*J11 -> 21 | L11: =Assumptions!$B$10*(1-Assumptions!$B$12)+Assumptions!$B$11*Assumptions!$B$12 -> 46.06 | M11: =K11*L11 -> 967.26 | N11: =((IF(A11<=Assumptions!$B$91,Assumptions!$B$90,IF(A11>=Assumptions!$B$92,1,Assumptions!$B$90+(1-Assumptions!$B$90)*(A11-Assumptions!$B$91)/(Assumptions!$B$92-Assumptions!$B$91))))*Assumptions!$B$81*Assumptions!$B$75+Assumptions!$B$82)*(1+Assumptions!$B$83)/12 -> 9583.3333 | O11: =M11*Assumptions!$B$33 -> 822.171 | P11: =O11-N11 -> -8761.1623 | Q11: =IF(A11>=Assumptions!$B$45,A11-Assumptions!$B$45+1,"") | R11: =IF(Q11="","Not yet launched",IF(Q11<=6,"CP1: Launch",IF(Q11<=18,"CP2: Scale",IF(Q11<=36,"CP3: Mature","CP4: Steady")))) -> Not yet launched | S11: =IF(Q11="",0,Assumptions!$B$46) -> 0 | T11: =IF(Q11="",0,IF(Q11<=6,Assumptions!$B$14,IF(Q11<=18,Assumptions!$B$15,IF(Q11<=36,Assumptions!$B$16,Assumptions!$B$17)))) -> 0 | U11: =IF(Q11="",0,IF(Q11=1,Assumptions!$B$65,ROUND(MAX(W10,1)*T11,0))) -> 0 | V11: =IF(Q11="",0,ROUND(W10*Assumptions!$B$49,0)) -> 0 | W11: =IF(Q11="",0,MIN(W10+U11-V11,S11)) -> 0 | X11: =IF(Q11="",0,Assumptions!$B$56) -> 0 | Y11: =W11*X11 -> 0 | Z11: =L11 -> 46.06 | AA11: =Y11*Z11 -> 0 | AB11: =IF(A11=Assumptions!$B$45,Assumptions!$B$47+Assumptions!$B$48,IF(A11>Assumptions!$B$45,Assumptions!$B$47,0)) -> 0 | AC11: =AA11*Assumptions!$B$33 -> 0 | AD11: =I11+W11 -> 21 | AE11: =M11+AA11 -> 967.26 | AF11: =N11+AB11+AJ11+AK11+AL11+Assumptions!$B$68 -> 9735.1774 | AG11: =O11+AC11 -> 822.171 | AH11: =AG11-AF11 -> -8913.0064 | AI11: =IFERROR((AD11-AD10)/AD10,"") -> 0.16666667 | AJ11: =MAX(Assumptions!$B$71,Assumptions!$B$69*0.5^(A11/Assumptions!$B$70))+Assumptions!$B$72*(K11+Y11) -> 101.84408 | AK11: =IF(AND(Assumptions!$B$76=1,A11>=Assumptions!$B$77),Assumptions!$B$78/12,0) -> 0 | AL11: =IF(AND(Assumptions!$B$86=1,Q11<>""),Assumptions!$B$87/12,0) -> 0
A12: 11 | B12: Jun 2027 | C12: =IF(A12<=12,1,IF(A12<=24,2,IF(A12<=36,3,4))) -> 1 | D12: =IF(A12<=6,"P1: Pilot->Seed",IF(A12<=18,"P2: Scale/Series A",IF(A12<=36,"P3: Post-Series A","P4: Maturity"))) -> P2: Scale/Series A | E12: =IF(C12=1,Assumptions!$B$5,IF(C12=2,Assumptions!$B$6,IF(C12=3,Assumptions!$B$7,Assumptions!$B$8))) -> 1200 | F12: =IF(A12<=6,Assumptions!$B$14,IF(A12<=18,Assumptions!$B$15,IF(A12<=36,Assumptions!$B$16,Assumptions!$B$17))) -> 0.14 | G12: =ROUND(MAX(I11,1)*F12,0) -> 3 | H12: =ROUND(I11*Assumptions!$B$18,0) -> 0 | I12: =MIN(I11+G12-H12,E12) -> 24 | J12: =Assumptions!$B$25 -> 1 | K12: =I12*J12 -> 24 | L12: =Assumptions!$B$10*(1-Assumptions!$B$12)+Assumptions!$B$11*Assumptions!$B$12 -> 46.06 | M12: =K12*L12 -> 1105.44 | N12: =((IF(A12<=Assumptions!$B$91,Assumptions!$B$90,IF(A12>=Assumptions!$B$92,1,Assumptions!$B$90+(1-Assumptions!$B$90)*(A12-Assumptions!$B$91)/(Assumptions!$B$92-Assumptions!$B$91))))*Assumptions!$B$81*Assumptions!$B$75+Assumptions!$B$82)*(1+Assumptions!$B$83)/12 -> 11659.722 | O12: =M12*Assumptions!$B$33 -> 939.624 | P12: =O12-N12 -> -10720.098 | Q12: =IF(A12>=Assumptions!$B$45,A12-Assumptions!$B$45+1,"") | R12: =IF(Q12="","Not yet launched",IF(Q12<=6,"CP1: Launch",IF(Q12<=18,"CP2: Scale",IF(Q12<=36,"CP3: Mature","CP4: Steady")))) -> Not yet launched | S12: =IF(Q12="",0,Assumptions!$B$46) -> 0 | T12: =IF(Q12="",0,IF(Q12<=6,Assumptions!$B$14,IF(Q12<=18,Assumptions!$B$15,IF(Q12<=36,Assumptions!$B$16,Assumptions!$B$17)))) -> 0 | U12: =IF(Q12="",0,IF(Q12=1,Assumptions!$B$65,ROUND(MAX(W11,1)*T12,0))) -> 0 | V12: =IF(Q12="",0,ROUND(W11*Assumptions!$B$49,0)) -> 0 | W12: =IF(Q12="",0,MIN(W11+U12-V12,S12)) -> 0 | X12: =IF(Q12="",0,Assumptions!$B$57) -> 0 | Y12: =W12*X12 -> 0 | Z12: =L12 -> 46.06 | AA12: =Y12*Z12 -> 0 | AB12: =IF(A12=Assumptions!$B$45,Assumptions!$B$47+Assumptions!$B$48,IF(A12>Assumptions!$B$45,Assumptions!$B$47,0)) -> 0 | AC12: =AA12*Assumptions!$B$33 -> 0 | AD12: =I12+W12 -> 24 | AE12: =M12+AA12 -> 1105.44 | AF12: =N12+AB12+AJ12+AK12+AL12+Assumptions!$B$68 -> 11802.307 | AG12: =O12+AC12 -> 939.624 | AH12: =AG12-AF12 -> -10862.683 | AI12: =IFERROR((AD12-AD11)/AD11,"") -> 0.14285714 | AJ12: =MAX(Assumptions!$B$71,Assumptions!$B$69*0.5^(A12/Assumptions!$B$70))+Assumptions!$B$72*(K12+Y12) -> 92.584654 | AK12: =IF(AND(Assumptions!$B$76=1,A12>=Assumptions!$B$77),Assumptions!$B$78/12,0) -> 0 | AL12: =IF(AND(Assumptions!$B$86=1,Q12<>""),Assumptions!$B$87/12,0) -> 0
A13: 12 | B13: Jul 2027 | C13: =IF(A13<=12,1,IF(A13<=24,2,IF(A13<=36,3,4))) -> 1 | D13: =IF(A13<=6,"P1: Pilot->Seed",IF(A13<=18,"P2: Scale/Series A",IF(A13<=36,"P3: Post-Series A","P4: Maturity"))) -> P2: Scale/Series A | E13: =IF(C13=1,Assumptions!$B$5,IF(C13=2,Assumptions!$B$6,IF(C13=3,Assumptions!$B$7,Assumptions!$B$8))) -> 1200 | F13: =IF(A13<=6,Assumptions!$B$14,IF(A13<=18,Assumptions!$B$15,IF(A13<=36,Assumptions!$B$16,Assumptions!$B$17))) -> 0.14 | G13: =ROUND(MAX(I12,1)*F13,0) -> 3 | H13: =ROUND(I12*Assumptions!$B$18,0) -> 0 | I13: =MIN(I12+G13-H13,E13) -> 27 | J13: =Assumptions!$B$26 -> 1 | K13: =I13*J13 -> 27 | L13: =Assumptions!$B$10*(1-Assumptions!$B$12)+Assumptions!$B$11*Assumptions!$B$12 -> 46.06 | M13: =K13*L13 -> 1243.62 | N13: =((IF(A13<=Assumptions!$B$91,Assumptions!$B$90,IF(A13>=Assumptions!$B$92,1,Assumptions!$B$90+(1-Assumptions!$B$90)*(A13-Assumptions!$B$91)/(Assumptions!$B$92-Assumptions!$B$91))))*Assumptions!$B$81*Assumptions!$B$75+Assumptions!$B$82)*(1+Assumptions!$B$83)/12 -> 13736.111 | O13: =M13*Assumptions!$B$33 -> 1057.077 | P13: =O13-N13 -> -12679.034 | Q13: =IF(A13>=Assumptions!$B$45,A13-Assumptions!$B$45+1,"") | R13: =IF(Q13="","Not yet launched",IF(Q13<=6,"CP1: Launch",IF(Q13<=18,"CP2: Scale",IF(Q13<=36,"CP3: Mature","CP4: Steady")))) -> Not yet launched | S13: =IF(Q13="",0,Assumptions!$B$46) -> 0 | T13: =IF(Q13="",0,IF(Q13<=6,Assumptions!$B$14,IF(Q13<=18,Assumptions!$B$15,IF(Q13<=36,Assumptions!$B$16,Assumptions!$B$17)))) -> 0 | U13: =IF(Q13="",0,IF(Q13=1,Assumptions!$B$65,ROUND(MAX(W12,1)*T13,0))) -> 0 | V13: =IF(Q13="",0,ROUND(W12*Assumptions!$B$49,0)) -> 0 | W13: =IF(Q13="",0,MIN(W12+U13-V13,S13)) -> 0 | X13: =IF(Q13="",0,Assumptions!$B$58) -> 0 | Y13: =W13*X13 -> 0 | Z13: =L13 -> 46.06 | AA13: =Y13*Z13 -> 0 | AB13: =IF(A13=Assumptions!$B$45,Assumptions!$B$47+Assumptions!$B$48,IF(A13>Assumptions!$B$45,Assumptions!$B$47,0)) -> 0 | AC13: =AA13*Assumptions!$B$33 -> 0 | AD13: =I13+W13 -> 27 | AE13: =M13+AA13 -> 1243.62 | AF13: =N13+AB13+AJ13+AK13+AL13+Assumptions!$B$68 -> 13870.561 | AG13: =O13+AC13 -> 1057.077 | AH13: =AG13-AF13 -> -12813.484 | AI13: =IFERROR((AD13-AD12)/AD12,"") -> 0.125 | AJ13: =MAX(Assumptions!$B$71,Assumptions!$B$69*0.5^(A13/Assumptions!$B$70))+Assumptions!$B$72*(K13+Y13) -> 84.45 | AK13: =IF(AND(Assumptions!$B$76=1,A13>=Assumptions!$B$77),Assumptions!$B$78/12,0) -> 0 | AL13: =IF(AND(Assumptions!$B$86=1,Q13<>""),Assumptions!$B$87/12,0) -> 0
A14: 13 | B14: Aug 2027 | C14: =IF(A14<=12,1,IF(A14<=24,2,IF(A14<=36,3,4))) -> 2 | D14: =IF(A14<=6,"P1: Pilot->Seed",IF(A14<=18,"P2: Scale/Series A",IF(A14<=36,"P3: Post-Series A","P4: Maturity"))) -> P2: Scale/Series A | E14: =IF(C14=1,Assumptions!$B$5,IF(C14=2,Assumptions!$B$6,IF(C14=3,Assumptions!$B$7,Assumptions!$B$8))) -> 4500 | F14: =IF(A14<=6,Assumptions!$B$14,IF(A14<=18,Assumptions!$B$15,IF(A14<=36,Assumptions!$B$16,Assumptions!$B$17))) -> 0.14 | G14: =ROUND(MAX(I13,1)*F14,0) -> 4 | H14: =ROUND(I13*Assumptions!$B$18,0) -> 1 | I14: =MIN(I13+G14-H14,E14) -> 30 | J14: =Assumptions!$B$27 -> 1 | K14: =I14*J14 -> 30 | L14: =Assumptions!$B$10*(1-Assumptions!$B$12)+Assumptions!$B$11*Assumptions!$B$12 -> 46.06 | M14: =K14*L14 -> 1381.8 | N14: =((IF(A14<=Assumptions!$B$91,Assumptions!$B$90,IF(A14>=Assumptions!$B$92,1,Assumptions!$B$90+(1-Assumptions!$B$90)*(A14-Assumptions!$B$91)/(Assumptions!$B$92-Assumptions!$B$91))))*Assumptions!$B$81*Assumptions!$B$75+Assumptions!$B$82)*(1+Assumptions!$B$83)/12 -> 15812.5 | O14: =M14*Assumptions!$B$33 -> 1174.53 | P14: =O14-N14 -> -14637.97 | Q14: =IF(A14>=Assumptions!$B$45,A14-Assumptions!$B$45+1,"") -> 1 | R14: =IF(Q14="","Not yet launched",IF(Q14<=6,"CP1: Launch",IF(Q14<=18,"CP2: Scale",IF(Q14<=36,"CP3: Mature","CP4: Steady")))) -> CP1: Launch | S14: =IF(Q14="",0,Assumptions!$B$46) -> 2000 | T14: =IF(Q14="",0,IF(Q14<=6,Assumptions!$B$14,IF(Q14<=18,Assumptions!$B$15,IF(Q14<=36,Assumptions!$B$16,Assumptions!$B$17)))) -> 0.35 | U14: =IF(Q14="",0,IF(Q14=1,Assumptions!$B$65,ROUND(MAX(W13,1)*T14,0))) -> 2 | V14: =IF(Q14="",0,ROUND(W13*Assumptions!$B$49,0)) -> 0 | W14: =IF(Q14="",0,MIN(W13+U14-V14,S14)) -> 2 | X14: =IF(Q14="",0,Assumptions!$B$59) -> 0.35 | Y14: =W14*X14 -> 0.7 | Z14: =L14 -> 46.06 | AA14: =Y14*Z14 -> 32.242 | AB14: =IF(A14=Assumptions!$B$45,Assumptions!$B$47+Assumptions!$B$48,IF(A14>Assumptions!$B$45,Assumptions!$B$47,0)) -> 40050 | AC14: =AA14*Assumptions!$B$33 -> 27.4057 | AD14: =I14+W14 -> 32 | AE14: =M14+AA14 -> 1414.042 | AF14: =N14+AB14+AJ14+AK14+AL14+Assumptions!$B$68 -> 60581.578 | AG14: =O14+AC14 -> 1201.9357 | AH14: =AG14-AF14 -> -59379.643 | AI14: =IFERROR((AD14-AD13)/AD13,"") -> 0.18518519 | AJ14: =MAX(Assumptions!$B$71,Assumptions!$B$69*0.5^(A14/Assumptions!$B$70))+Assumptions!$B$72*(K14+Y14) -> 85.745 | AK14: =IF(AND(Assumptions!$B$76=1,A14>=Assumptions!$B$77),Assumptions!$B$78/12,0) -> 4583.3333 | AL14: =IF(AND(Assumptions!$B$86=1,Q14<>""),Assumptions!$B$87/12,0) -> 0
A15: 14 | B15: Sep 2027 | C15: =IF(A15<=12,1,IF(A15<=24,2,IF(A15<=36,3,4))) -> 2 | D15: =IF(A15<=6,"P1: Pilot->Seed",IF(A15<=18,"P2: Scale/Series A",IF(A15<=36,"P3: Post-Series A","P4: Maturity"))) -> P2: Scale/Series A | E15: =IF(C15=1,Assumptions!$B$5,IF(C15=2,Assumptions!$B$6,IF(C15=3,Assumptions!$B$7,Assumptions!$B$8))) -> 4500 | F15: =IF(A15<=6,Assumptions!$B$14,IF(A15<=18,Assumptions!$B$15,IF(A15<=36,Assumptions!$B$16,Assumptions!$B$17))) -> 0.14 | G15: =ROUND(MAX(I14,1)*F15,0) -> 4 | H15: =ROUND(I14*Assumptions!$B$18,0) -> 1 | I15: =MIN(I14+G15-H15,E15) -> 33 | J15: =Assumptions!$B$28 -> 1 | K15: =I15*J15 -> 33 | L15: =Assumptions!$B$10*(1-Assumptions!$B$12)+Assumptions!$B$11*Assumptions!$B$12 -> 46.06 | M15: =K15*L15 -> 1519.98 | N15: =((IF(A15<=Assumptions!$B$91,Assumptions!$B$90,IF(A15>=Assumptions!$B$92,1,Assumptions!$B$90+(1-Assumptions!$B$90)*(A15-Assumptions!$B$91)/(Assumptions!$B$92-Assumptions!$B$91))))*Assumptions!$B$81*Assumptions!$B$75+Assumptions!$B$82)*(1+Assumptions!$B$83)/12 -> 17888.889 | O15: =M15*Assumptions!$B$33 -> 1291.983 | P15: =O15-N15 -> -16596.906 | Q15: =IF(A15>=Assumptions!$B$45,A15-Assumptions!$B$45+1,"") -> 2 | R15: =IF(Q15="","Not yet launched",IF(Q15<=6,"CP1: Launch",IF(Q15<=18,"CP2: Scale",IF(Q15<=36,"CP3: Mature","CP4: Steady")))) -> CP1: Launch | S15: =IF(Q15="",0,Assumptions!$B$46) -> 2000 | T15: =IF(Q15="",0,IF(Q15<=6,Assumptions!$B$14,IF(Q15<=18,Assumptions!$B$15,IF(Q15<=36,Assumptions!$B$16,Assumptions!$B$17)))) -> 0.35 | U15: =IF(Q15="",0,IF(Q15=1,Assumptions!$B$65,ROUND(MAX(W14,1)*T15,0))) -> 1 | V15: =IF(Q15="",0,ROUND(W14*Assumptions!$B$49,0)) -> 0 | W15: =IF(Q15="",0,MIN(W14+U15-V15,S15)) -> 3 | X15: =IF(Q15="",0,Assumptions!$B$60) -> 0.35 | Y15: =W15*X15 -> 1.05 | Z15: =L15 -> 46.06 | AA15: =Y15*Z15 -> 48.363 | AB15: =IF(A15=Assumptions!$B$45,Assumptions!$B$47+Assumptions!$B$48,IF(A15>Assumptions!$B$45,Assumptions!$B$47,0)) -> 50 | AC15: =AA15*Assumptions!$B$33 -> 41.10855 | AD15: =I15+W15 -> 36 | AE15: =M15+AA15 -> 1568.343 | AF15: =N15+AB15+AJ15+AK15+AL15+Assumptions!$B$68 -> 22659.14 | AG15: =O15+AC15 -> 1333.0916 | AH15: =AG15-AF15 -> -21326.048 | AI15: =IFERROR((AD15-AD14)/AD14,"") -> 0.125 | AJ15: =MAX(Assumptions!$B$71,Assumptions!$B$69*0.5^(A15/Assumptions!$B$70))+Assumptions!$B$72*(K15+Y15) -> 86.9175 | AK15: =IF(AND(Assumptions!$B$76=1,A15>=Assumptions!$B$77),Assumptions!$B$78/12,0) -> 4583.3333 | AL15: =IF(AND(Assumptions!$B$86=1,Q15<>""),Assumptions!$B$87/12,0) -> 0
A16: 15 | B16: Oct 2027 | C16: =IF(A16<=12,1,IF(A16<=24,2,IF(A16<=36,3,4))) -> 2 | D16: =IF(A16<=6,"P1: Pilot->Seed",IF(A16<=18,"P2: Scale/Series A",IF(A16<=36,"P3: Post-Series A","P4: Maturity"))) -> P2: Scale/Series A | E16: =IF(C16=1,Assumptions!$B$5,IF(C16=2,Assumptions!$B$6,IF(C16=3,Assumptions!$B$7,Assumptions!$B$8))) -> 4500 | F16: =IF(A16<=6,Assumptions!$B$14,IF(A16<=18,Assumptions!$B$15,IF(A16<=36,Assumptions!$B$16,Assumptions!$B$17))) -> 0.14 | G16: =ROUND(MAX(I15,1)*F16,0) -> 5 | H16: =ROUND(I15*Assumptions!$B$18,0) -> 1 | I16: =MIN(I15+G16-H16,E16) -> 37 | J16: =Assumptions!$B$29 -> 0.85 | K16: =I16*J16 -> 31.45 | L16: =Assumptions!$B$10*(1-Assumptions!$B$12)+Assumptions!$B$11*Assumptions!$B$12 -> 46.06 | M16: =K16*L16 -> 1448.587 | N16: =((IF(A16<=Assumptions!$B$91,Assumptions!$B$90,IF(A16>=Assumptions!$B$92,1,Assumptions!$B$90+(1-Assumptions!$B$90)*(A16-Assumptions!$B$91)/(Assumptions!$B$92-Assumptions!$B$91))))*Assumptions!$B$81*Assumptions!$B$75+Assumptions!$B$82)*(1+Assumptions!$B$83)/12 -> 19965.278 | O16: =M16*Assumptions!$B$33 -> 1231.299 | P16: =O16-N16 -> -18733.979 | Q16: =IF(A16>=Assumptions!$B$45,A16-Assumptions!$B$45+1,"") -> 3 | R16: =IF(Q16="","Not yet launched",IF(Q16<=6,"CP1: Launch",IF(Q16<=18,"CP2: Scale",IF(Q16<=36,"CP3: Mature","CP4: Steady")))) -> CP1: Launch | S16: =IF(Q16="",0,Assumptions!$B$46) -> 2000 | T16: =IF(Q16="",0,IF(Q16<=6,Assumptions!$B$14,IF(Q16<=18,Assumptions!$B$15,IF(Q16<=36,Assumptions!$B$16,Assumptions!$B$17)))) -> 0.35 | U16: =IF(Q16="",0,IF(Q16=1,Assumptions!$B$65,ROUND(MAX(W15,1)*T16,0))) -> 1 | V16: =IF(Q16="",0,ROUND(W15*Assumptions!$B$49,0)) -> 0 | W16: =IF(Q16="",0,MIN(W15+U16-V16,S16)) -> 4 | X16: =IF(Q16="",0,Assumptions!$B$61) -> 0.4 | Y16: =W16*X16 -> 1.6 | Z16: =L16 -> 46.06 | AA16: =Y16*Z16 -> 73.696 | AB16: =IF(A16=Assumptions!$B$45,Assumptions!$B$47+Assumptions!$B$48,IF(A16>Assumptions!$B$45,Assumptions!$B$47,0)) -> 50 | AC16: =AA16*Assumptions!$B$33 -> 62.6416 | AD16: =I16+W16 -> 41 | AE16: =M16+AA16 -> 1522.283 | AF16: =N16+AB16+AJ16+AK16+AL16+Assumptions!$B$68 -> 24735.179 | AG16: =O16+AC16 -> 1293.9406 | AH16: =AG16-AF16 -> -23441.238 | AI16: =IFERROR((AD16-AD15)/AD15,"") -> 0.13888889 | AJ16: =MAX(Assumptions!$B$71,Assumptions!$B$69*0.5^(A16/Assumptions!$B$70))+Assumptions!$B$72*(K16+Y16) -> 86.5675 | AK16: =IF(AND(Assumptions!$B$76=1,A16>=Assumptions!$B$77),Assumptions!$B$78/12,0) -> 4583.3333 | AL16: =IF(AND(Assumptions!$B$86=1,Q16<>""),Assumptions!$B$87/12,0) -> 0
A17: 16 | B17: Nov 2027 | C17: =IF(A17<=12,1,IF(A17<=24,2,IF(A17<=36,3,4))) -> 2 | D17: =IF(A17<=6,"P1: Pilot->Seed",IF(A17<=18,"P2: Scale/Series A",IF(A17<=36,"P3: Post-Series A","P4: Maturity"))) -> P2: Scale/Series A | E17: =IF(C17=1,Assumptions!$B$5,IF(C17=2,Assumptions!$B$6,IF(C17=3,Assumptions!$B$7,Assumptions!$B$8))) -> 4500 | F17: =IF(A17<=6,Assumptions!$B$14,IF(A17<=18,Assumptions!$B$15,IF(A17<=36,Assumptions!$B$16,Assumptions!$B$17))) -> 0.14 | G17: =ROUND(MAX(I16,1)*F17,0) -> 5 | H17: =ROUND(I16*Assumptions!$B$18,0) -> 1 | I17: =MIN(I16+G17-H17,E17) -> 41 | J17: =Assumptions!$B$30 -> 0.45 | K17: =I17*J17 -> 18.45 | L17: =Assumptions!$B$10*(1-Assumptions!$B$12)+Assumptions!$B$11*Assumptions!$B$12 -> 46.06 | M17: =K17*L17 -> 849.807 | N17: =((IF(A17<=Assumptions!$B$91,Assumptions!$B$90,IF(A17>=Assumptions!$B$92,1,Assumptions!$B$90+(1-Assumptions!$B$90)*(A17-Assumptions!$B$91)/(Assumptions!$B$92-Assumptions!$B$91))))*Assumptions!$B$81*Assumptions!$B$75+Assumptions!$B$82)*(1+Assumptions!$B$83)/12 -> 22041.667 | O17: =M17*Assumptions!$B$33 -> 722.33595 | P17: =O17-N17 -> -21319.331 | Q17: =IF(A17>=Assumptions!$B$45,A17-Assumptions!$B$45+1,"") -> 4 | R17: =IF(Q17="","Not yet launched",IF(Q17<=6,"CP1: Launch",IF(Q17<=18,"CP2: Scale",IF(Q17<=36,"CP3: Mature","CP4: Steady")))) -> CP1: Launch | S17: =IF(Q17="",0,Assumptions!$B$46) -> 2000 | T17: =IF(Q17="",0,IF(Q17<=6,Assumptions!$B$14,IF(Q17<=18,Assumptions!$B$15,IF(Q17<=36,Assumptions!$B$16,Assumptions!$B$17)))) -> 0.35 | U17: =IF(Q17="",0,IF(Q17=1,Assumptions!$B$65,ROUND(MAX(W16,1)*T17,0))) -> 1 | V17: =IF(Q17="",0,ROUND(W16*Assumptions!$B$49,0)) -> 0 | W17: =IF(Q17="",0,MIN(W16+U17-V17,S17)) -> 5 | X17: =IF(Q17="",0,Assumptions!$B$62) -> 0.55 | Y17: =W17*X17 -> 2.75 | Z17: =L17 -> 46.06 | AA17: =Y17*Z17 -> 126.665 | AB17: =IF(A17=Assumptions!$B$45,Assumptions!$B$47+Assumptions!$B$48,IF(A17>Assumptions!$B$45,Assumptions!$B$47,0)) -> 50 | AC17: =AA17*Assumptions!$B$33 -> 107.66525 | AD17: =I17+W17 -> 46 | AE17: =M17+AA17 -> 976.472 | AF17: =N17+AB17+AJ17+AK17+AL17+Assumptions!$B$68 -> 26807.42 | AG17: =O17+AC17 -> 830.0012 | AH17: =AG17-AF17 -> -25977.419 | AI17: =IFERROR((AD17-AD16)/AD16,"") -> 0.12195122 | AJ17: =MAX(Assumptions!$B$71,Assumptions!$B$69*0.5^(A17/Assumptions!$B$70))+Assumptions!$B$72*(K17+Y17) -> 82.42 | AK17: =IF(AND(Assumptions!$B$76=1,A17>=Assumptions!$B$77),Assumptions!$B$78/12,0) -> 4583.3333 | AL17: =IF(AND(Assumptions!$B$86=1,Q17<>""),Assumptions!$B$87/12,0) -> 0
A18: 17 | B18: Dec 2027 | C18: =IF(A18<=12,1,IF(A18<=24,2,IF(A18<=36,3,4))) -> 2 | D18: =IF(A18<=6,"P1: Pilot->Seed",IF(A18<=18,"P2: Scale/Series A",IF(A18<=36,"P3: Post-Series A","P4: Maturity"))) -> P2: Scale/Series A | E18: =IF(C18=1,Assumptions!$B$5,IF(C18=2,Assumptions!$B$6,IF(C18=3,Assumptions!$B$7,Assumptions!$B$8))) -> 4500 | F18: =IF(A18<=6,Assumptions!$B$14,IF(A18<=18,Assumptions!$B$15,IF(A18<=36,Assumptions!$B$16,Assumptions!$B$17))) -> 0.14 | G18: =ROUND(MAX(I17,1)*F18,0) -> 6 | H18: =ROUND(I17*Assumptions!$B$18,0) -> 1 | I18: =MIN(I17+G18-H18,E18) -> 46 | J18: =Assumptions!$B$31 -> 0.35 | K18: =I18*J18 -> 16.1 | L18: =Assumptions!$B$10*(1-Assumptions!$B$12)+Assumptions!$B$11*Assumptions!$B$12 -> 46.06 | M18: =K18*L18 -> 741.566 | N18: =((IF(A18<=Assumptions!$B$91,Assumptions!$B$90,IF(A18>=Assumptions!$B$92,1,Assumptions!$B$90+(1-Assumptions!$B$90)*(A18-Assumptions!$B$91)/(Assumptions!$B$92-Assumptions!$B$91))))*Assumptions!$B$81*Assumptions!$B$75+Assumptions!$B$82)*(1+Assumptions!$B$83)/12 -> 24118.056 | O18: =M18*Assumptions!$B$33 -> 630.3311 | P18: =O18-N18 -> -23487.724 | Q18: =IF(A18>=Assumptions!$B$45,A18-Assumptions!$B$45+1,"") -> 5 | R18: =IF(Q18="","Not yet launched",IF(Q18<=6,"CP1: Launch",IF(Q18<=18,"CP2: Scale",IF(Q18<=36,"CP3: Mature","CP4: Steady")))) -> CP1: Launch | S18: =IF(Q18="",0,Assumptions!$B$46) -> 2000 | T18: =IF(Q18="",0,IF(Q18<=6,Assumptions!$B$14,IF(Q18<=18,Assumptions!$B$15,IF(Q18<=36,Assumptions!$B$16,Assumptions!$B$17)))) -> 0.35 | U18: =IF(Q18="",0,IF(Q18=1,Assumptions!$B$65,ROUND(MAX(W17,1)*T18,0))) -> 2 | V18: =IF(Q18="",0,ROUND(W17*Assumptions!$B$49,0)) -> 0 | W18: =IF(Q18="",0,MIN(W17+U18-V18,S18)) -> 7 | X18: =IF(Q18="",0,Assumptions!$B$63) -> 0.9 | Y18: =W18*X18 -> 6.3 | Z18: =L18 -> 46.06 | AA18: =Y18*Z18 -> 290.178 | AB18: =IF(A18=Assumptions!$B$45,Assumptions!$B$47+Assumptions!$B$48,IF(A18>Assumptions!$B$45,Assumptions!$B$47,0)) -> 50 | AC18: =AA18*Assumptions!$B$33 -> 246.6513 | AD18: =I18+W18 -> 53 | AE18: =M18+AA18 -> 1031.744 | AF18: =N18+AB18+AJ18+AK18+AL18+Assumptions!$B$68 -> 28884.229 | AG18: =O18+AC18 -> 876.9824 | AH18: =AG18-AF18 -> -28007.246 | AI18: =IFERROR((AD18-AD17)/AD17,"") -> 0.15217391 | AJ18: =MAX(Assumptions!$B$71,Assumptions!$B$69*0.5^(A18/Assumptions!$B$70))+Assumptions!$B$72*(K18+Y18) -> 82.84 | AK18: =IF(AND(Assumptions!$B$76=1,A18>=Assumptions!$B$77),Assumptions!$B$78/12,0) -> 4583.3333 | AL18: =IF(AND(Assumptions!$B$86=1,Q18<>""),Assumptions!$B$87/12,0) -> 0
A19: 18 | B19: Jan 2028 | C19: =IF(A19<=12,1,IF(A19<=24,2,IF(A19<=36,3,4))) -> 2 | D19: =IF(A19<=6,"P1: Pilot->Seed",IF(A19<=18,"P2: Scale/Series A",IF(A19<=36,"P3: Post-Series A","P4: Maturity"))) -> P2: Scale/Series A | E19: =IF(C19=1,Assumptions!$B$5,IF(C19=2,Assumptions!$B$6,IF(C19=3,Assumptions!$B$7,Assumptions!$B$8))) -> 4500 | F19: =IF(A19<=6,Assumptions!$B$14,IF(A19<=18,Assumptions!$B$15,IF(A19<=36,Assumptions!$B$16,Assumptions!$B$17))) -> 0.14 | G19: =ROUND(MAX(I18,1)*F19,0) -> 6 | H19: =ROUND(I18*Assumptions!$B$18,0) -> 1 | I19: =MIN(I18+G19-H19,E19) -> 51 | J19: =Assumptions!$B$20 -> 0.35 | K19: =I19*J19 -> 17.85 | L19: =Assumptions!$B$10*(1-Assumptions!$B$12)+Assumptions!$B$11*Assumptions!$B$12 -> 46.06 | M19: =K19*L19 -> 822.171 | N19: =((IF(A19<=Assumptions!$B$91,Assumptions!$B$90,IF(A19>=Assumptions!$B$92,1,Assumptions!$B$90+(1-Assumptions!$B$90)*(A19-Assumptions!$B$91)/(Assumptions!$B$92-Assumptions!$B$91))))*Assumptions!$B$81*Assumptions!$B$75+Assumptions!$B$82)*(1+Assumptions!$B$83)/12 -> 26194.444 | O19: =M19*Assumptions!$B$33 -> 698.84535 | P19: =O19-N19 -> -25495.599 | Q19: =IF(A19>=Assumptions!$B$45,A19-Assumptions!$B$45+1,"") -> 6 | R19: =IF(Q19="","Not yet launched",IF(Q19<=6,"CP1: Launch",IF(Q19<=18,"CP2: Scale",IF(Q19<=36,"CP3: Mature","CP4: Steady")))) -> CP1: Launch | S19: =IF(Q19="",0,Assumptions!$B$46) -> 2000 | T19: =IF(Q19="",0,IF(Q19<=6,Assumptions!$B$14,IF(Q19<=18,Assumptions!$B$15,IF(Q19<=36,Assumptions!$B$16,Assumptions!$B$17)))) -> 0.35 | U19: =IF(Q19="",0,IF(Q19=1,Assumptions!$B$65,ROUND(MAX(W18,1)*T19,0))) -> 2 | V19: =IF(Q19="",0,ROUND(W18*Assumptions!$B$49,0)) -> 0 | W19: =IF(Q19="",0,MIN(W18+U19-V19,S19)) -> 9 | X19: =IF(Q19="",0,Assumptions!$B$52) -> 1 | Y19: =W19*X19 -> 9 | Z19: =L19 -> 46.06 | AA19: =Y19*Z19 -> 414.54 | AB19: =IF(A19=Assumptions!$B$45,Assumptions!$B$47+Assumptions!$B$48,IF(A19>Assumptions!$B$45,Assumptions!$B$47,0)) -> 50 | AC19: =AA19*Assumptions!$B$33 -> 352.359 | AD19: =I19+W19 -> 60 | AE19: =M19+AA19 -> 1236.711 | AF19: =N19+AB19+AJ19+AK19+AL19+Assumptions!$B$68 -> 30962.175 | AG19: =O19+AC19 -> 1051.2043 | AH19: =AG19-AF19 -> -29910.971 | AI19: =IFERROR((AD19-AD18)/AD18,"") -> 0.13207547 | AJ19: =MAX(Assumptions!$B$71,Assumptions!$B$69*0.5^(A19/Assumptions!$B$70))+Assumptions!$B$72*(K19+Y19) -> 84.3975 | AK19: =IF(AND(Assumptions!$B$76=1,A19>=Assumptions!$B$77),Assumptions!$B$78/12,0) -> 4583.3333 | AL19: =IF(AND(Assumptions!$B$86=1,Q19<>""),Assumptions!$B$87/12,0) -> 0
A20: 19 | B20: Feb 2028 | C20: =IF(A20<=12,1,IF(A20<=24,2,IF(A20<=36,3,4))) -> 2 | D20: =IF(A20<=6,"P1: Pilot->Seed",IF(A20<=18,"P2: Scale/Series A",IF(A20<=36,"P3: Post-Series A","P4: Maturity"))) -> P3: Post-Series A | E20: =IF(C20=1,Assumptions!$B$5,IF(C20=2,Assumptions!$B$6,IF(C20=3,Assumptions!$B$7,Assumptions!$B$8))) -> 4500 | F20: =IF(A20<=6,Assumptions!$B$14,IF(A20<=18,Assumptions!$B$15,IF(A20<=36,Assumptions!$B$16,Assumptions!$B$17))) -> 0.08 | G20: =ROUND(MAX(I19,1)*F20,0) -> 4 | H20: =ROUND(I19*Assumptions!$B$18,0) -> 1 | I20: =MIN(I19+G20-H20,E20) -> 54 | J20: =Assumptions!$B$21 -> 0.35 | K20: =I20*J20 -> 18.9 | L20: =Assumptions!$B$10*(1-Assumptions!$B$12)+Assumptions!$B$11*Assumptions!$B$12 -> 46.06 | M20: =K20*L20 -> 870.534 | N20: =((IF(A20<=Assumptions!$B$91,Assumptions!$B$90,IF(A20>=Assumptions!$B$92,1,Assumptions!$B$90+(1-Assumptions!$B$90)*(A20-Assumptions!$B$91)/(Assumptions!$B$92-Assumptions!$B$91))))*Assumptions!$B$81*Assumptions!$B$75+Assumptions!$B$82)*(1+Assumptions!$B$83)/12 -> 28270.833 | O20: =M20*Assumptions!$B$33 -> 739.9539 | P20: =O20-N20 -> -27530.879 | Q20: =IF(A20>=Assumptions!$B$45,A20-Assumptions!$B$45+1,"") -> 7 | R20: =IF(Q20="","Not yet launched",IF(Q20<=6,"CP1: Launch",IF(Q20<=18,"CP2: Scale",IF(Q20<=36,"CP3: Mature","CP4: Steady")))) -> CP2: Scale | S20: =IF(Q20="",0,Assumptions!$B$46) -> 2000 | T20: =IF(Q20="",0,IF(Q20<=6,Assumptions!$B$14,IF(Q20<=18,Assumptions!$B$15,IF(Q20<=36,Assumptions!$B$16,Assumptions!$B$17)))) -> 0.14 | U20: =IF(Q20="",0,IF(Q20=1,Assumptions!$B$65,ROUND(MAX(W19,1)*T20,0))) -> 1 | V20: =IF(Q20="",0,ROUND(W19*Assumptions!$B$49,0)) -> 0 | W20: =IF(Q20="",0,MIN(W19+U20-V20,S20)) -> 10 | X20: =IF(Q20="",0,Assumptions!$B$53) -> 1 | Y20: =W20*X20 -> 10 | Z20: =L20 -> 46.06 | AA20: =Y20*Z20 -> 460.6 | AB20: =IF(A20=Assumptions!$B$45,Assumptions!$B$47+Assumptions!$B$48,IF(A20>Assumptions!$B$45,Assumptions!$B$47,0)) -> 50 | AC20: =AA20*Assumptions!$B$33 -> 391.51 | AD20: =I20+W20 -> 64 | AE20: =M20+AA20 -> 1331.134 | AF20: =N20+AB20+AJ20+AK20+AL20+Assumptions!$B$68 -> 33039.282 | AG20: =O20+AC20 -> 1131.4639 | AH20: =AG20-AF20 -> -31907.818 | AI20: =IFERROR((AD20-AD19)/AD19,"") -> 0.066666667 | AJ20: =MAX(Assumptions!$B$71,Assumptions!$B$69*0.5^(A20/Assumptions!$B$70))+Assumptions!$B$72*(K20+Y20) -> 85.115 | AK20: =IF(AND(Assumptions!$B$76=1,A20>=Assumptions!$B$77),Assumptions!$B$78/12,0) -> 4583.3333 | AL20: =IF(AND(Assumptions!$B$86=1,Q20<>""),Assumptions!$B$87/12,0) -> 0
A21: 20 | B21: Mar 2028 | C21: =IF(A21<=12,1,IF(A21<=24,2,IF(A21<=36,3,4))) -> 2 | D21: =IF(A21<=6,"P1: Pilot->Seed",IF(A21<=18,"P2: Scale/Series A",IF(A21<=36,"P3: Post-Series A","P4: Maturity"))) -> P3: Post-Series A | E21: =IF(C21=1,Assumptions!$B$5,IF(C21=2,Assumptions!$B$6,IF(C21=3,Assumptions!$B$7,Assumptions!$B$8))) -> 4500 | F21: =IF(A21<=6,Assumptions!$B$14,IF(A21<=18,Assumptions!$B$15,IF(A21<=36,Assumptions!$B$16,Assumptions!$B$17))) -> 0.08 | G21: =ROUND(MAX(I20,1)*F21,0) -> 4 | H21: =ROUND(I20*Assumptions!$B$18,0) -> 1 | I21: =MIN(I20+G21-H21,E21) -> 57 | J21: =Assumptions!$B$22 -> 0.55 | K21: =I21*J21 -> 31.35 | L21: =Assumptions!$B$10*(1-Assumptions!$B$12)+Assumptions!$B$11*Assumptions!$B$12 -> 46.06 | M21: =K21*L21 -> 1443.981 | N21: =((IF(A21<=Assumptions!$B$91,Assumptions!$B$90,IF(A21>=Assumptions!$B$92,1,Assumptions!$B$90+(1-Assumptions!$B$90)*(A21-Assumptions!$B$91)/(Assumptions!$B$92-Assumptions!$B$91))))*Assumptions!$B$81*Assumptions!$B$75+Assumptions!$B$82)*(1+Assumptions!$B$83)/12 -> 28270.833 | O21: =M21*Assumptions!$B$33 -> 1227.3838 | P21: =O21-N21 -> -27043.449 | Q21: =IF(A21>=Assumptions!$B$45,A21-Assumptions!$B$45+1,"") -> 8 | R21: =IF(Q21="","Not yet launched",IF(Q21<=6,"CP1: Launch",IF(Q21<=18,"CP2: Scale",IF(Q21<=36,"CP3: Mature","CP4: Steady")))) -> CP2: Scale | S21: =IF(Q21="",0,Assumptions!$B$46) -> 2000 | T21: =IF(Q21="",0,IF(Q21<=6,Assumptions!$B$14,IF(Q21<=18,Assumptions!$B$15,IF(Q21<=36,Assumptions!$B$16,Assumptions!$B$17)))) -> 0.14 | U21: =IF(Q21="",0,IF(Q21=1,Assumptions!$B$65,ROUND(MAX(W20,1)*T21,0))) -> 1 | V21: =IF(Q21="",0,ROUND(W20*Assumptions!$B$49,0)) -> 0 | W21: =IF(Q21="",0,MIN(W20+U21-V21,S21)) -> 11 | X21: =IF(Q21="",0,Assumptions!$B$54) -> 1 | Y21: =W21*X21 -> 11 | Z21: =L21 -> 46.06 | AA21: =Y21*Z21 -> 506.66 | AB21: =IF(A21=Assumptions!$B$45,Assumptions!$B$47+Assumptions!$B$48,IF(A21>Assumptions!$B$45,Assumptions!$B$47,0)) -> 50 | AC21: =AA21*Assumptions!$B$33 -> 430.661 | AD21: =I21+W21 -> 68 | AE21: =M21+AA21 -> 1950.641 | AF21: =N21+AB21+AJ21+AK21+AL21+Assumptions!$B$68 -> 33043.989 | AG21: =O21+AC21 -> 1658.0448 | AH21: =AG21-AF21 -> -31385.944 | AI21: =IFERROR((AD21-AD20)/AD20,"") -> 0.0625 | AJ21: =MAX(Assumptions!$B$71,Assumptions!$B$69*0.5^(A21/Assumptions!$B$70))+Assumptions!$B$72*(K21+Y21) -> 89.8225 | AK21: =IF(AND(Assumptions!$B$76=1,A21>=Assumptions!$B$77),Assumptions!$B$78/12,0) -> 4583.3333 | AL21: =IF(AND(Assumptions!$B$86=1,Q21<>""),Assumptions!$B$87/12,0) -> 0
A22: 21 | B22: Apr 2028 | C22: =IF(A22<=12,1,IF(A22<=24,2,IF(A22<=36,3,4))) -> 2 | D22: =IF(A22<=6,"P1: Pilot->Seed",IF(A22<=18,"P2: Scale/Series A",IF(A22<=36,"P3: Post-Series A","P4: Maturity"))) -> P3: Post-Series A | E22: =IF(C22=1,Assumptions!$B$5,IF(C22=2,Assumptions!$B$6,IF(C22=3,Assumptions!$B$7,Assumptions!$B$8))) -> 4500 | F22: =IF(A22<=6,Assumptions!$B$14,IF(A22<=18,Assumptions!$B$15,IF(A22<=36,Assumptions!$B$16,Assumptions!$B$17))) -> 0.08 | G22: =ROUND(MAX(I21,1)*F22,0) -> 5 | H22: =ROUND(I21*Assumptions!$B$18,0) -> 1 | I22: =MIN(I21+G22-H22,E22) -> 61 | J22: =Assumptions!$B$23 -> 0.85 | K22: =I22*J22 -> 51.85 | L22: =Assumptions!$B$10*(1-Assumptions!$B$12)+Assumptions!$B$11*Assumptions!$B$12 -> 46.06 | M22: =K22*L22 -> 2388.211 | N22: =((IF(A22<=Assumptions!$B$91,Assumptions!$B$90,IF(A22>=Assumptions!$B$92,1,Assumptions!$B$90+(1-Assumptions!$B$90)*(A22-Assumptions!$B$91)/(Assumptions!$B$92-Assumptions!$B$91))))*Assumptions!$B$81*Assumptions!$B$75+Assumptions!$B$82)*(1+Assumptions!$B$83)/12 -> 28270.833 | O22: =M22*Assumptions!$B$33 -> 2029.9794 | P22: =O22-N22 -> -26240.854 | Q22: =IF(A22>=Assumptions!$B$45,A22-Assumptions!$B$45+1,"") -> 9 | R22: =IF(Q22="","Not yet launched",IF(Q22<=6,"CP1: Launch",IF(Q22<=18,"CP2: Scale",IF(Q22<=36,"CP3: Mature","CP4: Steady")))) -> CP2: Scale | S22: =IF(Q22="",0,Assumptions!$B$46) -> 2000 | T22: =IF(Q22="",0,IF(Q22<=6,Assumptions!$B$14,IF(Q22<=18,Assumptions!$B$15,IF(Q22<=36,Assumptions!$B$16,Assumptions!$B$17)))) -> 0.14 | U22: =IF(Q22="",0,IF(Q22=1,Assumptions!$B$65,ROUND(MAX(W21,1)*T22,0))) -> 2 | V22: =IF(Q22="",0,ROUND(W21*Assumptions!$B$49,0)) -> 0 | W22: =IF(Q22="",0,MIN(W21+U22-V22,S22)) -> 13 | X22: =IF(Q22="",0,Assumptions!$B$55) -> 0.9 | Y22: =W22*X22 -> 11.7 | Z22: =L22 -> 46.06 | AA22: =Y22*Z22 -> 538.902 | AB22: =IF(A22=Assumptions!$B$45,Assumptions!$B$47+Assumptions!$B$48,IF(A22>Assumptions!$B$45,Assumptions!$B$47,0)) -> 50 | AC22: =AA22*Assumptions!$B$33 -> 458.0667 | AD22: =I22+W22 -> 74 | AE22: =M22+AA22 -> 2927.113 | AF22: =N22+AB22+AJ22+AK22+AL22+Assumptions!$B$68 -> 33051.409 | AG22: =O22+AC22 -> 2488.046 | AH22: =AG22-AF22 -> -30563.363 | AI22: =IFERROR((AD22-AD21)/AD21,"") -> 0.088235294 | AJ22: =MAX(Assumptions!$B$71,Assumptions!$B$69*0.5^(A22/Assumptions!$B$70))+Assumptions!$B$72*(K22+Y22) -> 97.2425 | AK22: =IF(AND(Assumptions!$B$76=1,A22>=Assumptions!$B$77),Assumptions!$B$78/12,0) -> 4583.3333 | AL22: =IF(AND(Assumptions!$B$86=1,Q22<>""),Assumptions!$B$87/12,0) -> 0
